Workbook
Name Slicer_Candidate_Status: #N/A
Name Slicer_Year_of_Profile_Submission: #N/A

Sheet Summary
B3: Count of Account | C3: Candidate Status | D3: Mandatory Skill
Y4: Total | Z4: Active | AC4: Active Total | AD4: C#.NET,.NET Core,MVC,REST API/Web APIs,JavaScript | AE4: C#.NET,.NET Core,MVC,REST API/Web APIs,JavaScript Total | AF4: Client IP | BA4: Client IP Total | BB4: Client Reject | CP4: Client Reject Total | CQ4: Dropped | FW4: Dropped Total | FX4: Duplicate | FY4: Duplicate Total | FZ4: Feedback pending from client | GC4: Feedback pending from client Total | GD4: Final Select | GE4: Final Select Total | GF4: Hold | GH4: Hold Total | GI4: Joined | GO4: Joined Total | GP4: L2 reject | GQ4: L2 reject Total | GR4: Level 1 interview Done | GS4: Level 1 interview Done Total | GT4: No show | GW4: No show Total | GX4: Not my requirement | GY4: Not my requirement Total | GZ4: Not responding the calls | HA4: Not responding the calls Total | HB4: Offered | HD4: Offered Total | HE4: On Hold | HJ4: On Hold Total | HK4: Position closed | HN4: Position closed Total | HO4: Position Hold | HP4: Position Hold Total | HQ4: Position hold | HR4: Position hold Total | HS4: Rec Screen IP | HY4: Rec Screen IP Total | HZ4: Rec Screen Reject | IF4: Rec Screen Reject Total | IG4: Req closed | II4: Req closed Total | IJ4: Sceening IP | IK4: Sceening IP Total | IL4: Schduled | IN4: Schduled Total | IO4: Screen IP | IT4: Screen IP Total | IU4: Screen Reject | LI4: Screen Reject Total | LJ4: Screen reject | LM4: Screen reject Total | LN4: Screen reject from client | LO4: Screen reject from client Total | LP4: Screening IP | OF4: Screening IP Total | OG4: Screening IP | OH4: Screening IP Total | OI4: Sourced | OM4: Sourced Total | ON4: Submitted | OY4: Submitted Total | OZ4: TBO | PE4: TBO Total | PF4: Tech 1 Reject | PH4: Tech 1 Reject Total | PI4: Tech1 IP | QR4: Tech1 IP Total | QS4: Tech1 Reject | RY4: Tech1 Reject Total | RZ4: Tech2 IP | SH4: Tech2 IP Total | SI4: Tech2 Reject | SN4: Tech2 Reject Total | SO4: Uploaded | SP4: Uploaded Total | SQ4: (blank) | TB4: (blank) Total | TC4: Grand Total
B5: Recruiter Name | C5: . Net Developer | D5: .net core | E5: 5-8y Oracle DBA with MongoDB | F5: DevOps | G5: Dot Net | H5: DOTNET | I5: DW/EBI | J5: Hadoop developer | K5: J2EE,SpringBoot, ,Angular, | L5: Java | M5: Java | N5: Java Developer | O5: Java,Spring,JSP,Apache,Tomcat,SOAP/REST | P5: JAVA/J2EE | Q5: Java/J2EE,Core Java,Spring Boot | R5: Mobility | S5: Oracle | T5: PL SQL | U5: PM | V5: Product Manager | W5: RPA | X5: SDET | Z5: .Netcore | AA5: .NetCore,Angular | AB5: It Security | AD5: Digizura Technologies | AF5: .net core | AG5: 2-5 yrs C# Selenium | AH5: 4y+ Andriod Developer with Flutter | AI5: 8-12y NodeJS,Angular,Typescript,REST API,Automation Web Services,Cloud,Kafka,RabbitMQ,NGNIX | AJ5: Android Developer | AK5: Asp.Net MVC, Entity Framework,Web api | AL5: C#.NET, Desktop app | AM5: Cyber Security | AN5: Dell Boomi | AO5: Dell Boomi | AP5: Dot Net | AQ5: DOTNET | AR5: Dotnet Core | AS5: Java,Selenium,API | AT5: Mobility | AU5: NodeJS Developer,JavaScript,Postgres,MySQL,Redis(No SQL)- | AV5: Product Manager with Mobile, Web | AW5: Product Manager with Mobile, Web | AX5: SDET | AY5: SW Automation Testing | AZ5: UI UX Designer | BB5: .NET,SQL,WEB API | BC5: Andriod Developer with Flutter | BD5: Android Developer | BE5: Asp.Net MVC, Entity Framework,Web api | BF5: Automation Testing | BG5: Azure/AWS DevOps,Infrastructure ,Terraform,Scripting | BH5: BRM | BI5: C# SELENIUM | BJ5: C#,.NET core | BK5: C#.NET, Desktop app | BL5: C#.Net,.NET Core, Angular | BM5: c,c++,linux | BN5: Cyber Recovery | BO5: DBA | BP5: Dot Net | BQ5: DOT NET DEVELOPER | BR5: DOTNET | BS5: DW/EBI | BT5: Install shield | BU5: iOS | BV5: Java | BW5: JAVA , Strong exp in spring boot | BX5: Java, Spring, Springboot, Hibernate | BY5: Java,Selenium,API | BZ5: Java/J2EE,Spring Boot, Microservices | CA5: Manual Tesing, QA | CB5: Mobile Automation | CC5: Mobility | CD5: MSSQL,SQL | CE5: Oracle BRM Testing | CF5: PM | CG5: Power BI | CH5: Product Manager | CI5: Project Manager | CJ5: Project Manager ,SDLC,AGILE | CK5: Project manager with release mngt ITIL | CL5: RPA | CM5: SDET | CN5: Technical PM | CO5: TPM(Technical Project Manager) | CQ5: - 8+ yrs java springboot microservices | CR5: .Net Core,Angular | CS5: .NET Core,Spring Boot,Microservices,Kafka | CT5: .NET, microservices | CU5: .NET,.NET Core,Spring Boot,Microservices,Kafka | CV5: .NET,SQL,WEB API | CW5: 2-5y C/C++ on Linux/Windows,Unit Testing,Automation | CX5: 4y+ Andriod Developer with Flutter | CY5: 4y+ Java/J2EE,Microserices,SpringBoot,Node JS | CZ5: 5-8y Java/J2EE,Spring boot and Nodejs | DA5: 5-8y Java/J2EE,Spring Boot,Hibernate,Restful Services,Junit - | DB5: 8-.NET Core,Spring Boot,Microservices,Kafka | DC5: 8-12y Full Stack Testing,Automation Testing,UX/API Layer,SQL | DD5: Ansible,GitLab,Jenkins | DE5: Azure/AWS DevOps,Infrastructure ,Terraform,Scripting | DF5: BRM | DG5: C# .Net, .NET Core, Web Api, Angular | DH5: C#.NET,.NET Core, Web API, MVC,Angular,Jquery | DI5: C#.NET,.NET Core, Web API, MVC,Angular,Jquery role | DJ5: C#.NET,.NET Core, Web API, MVC,Angular,Jquery role . | DK5: C,C++ Programming with Linux | DL5: c,c++,linux | DM5: C/C++ | DN5: Cyber Security | DO5: DevOps | DP5: Dot Net | DQ5: DOTNET | DR5: Dotnet Core | DS5: Install shield | DT5: iOS | DU5: IOS Developer | DV5: IOS Flutter | DW5: Java | DX5: JAVA , Strong exp in spring boot | DY5: JAVA ,Spring boot | DZ5: Java Developer | EA5: Java Selenium | EB5: Java, Springboot, Microservices | EC5: Java, springboot, Microservices, MongoDB, Node.Js | ED5: Java,Selenium,API | EE5: Java,Selenium,API | EF5: java,selenium,API testing | EG5: Java,Spring,Oracle | EH5: Java,Springboot | EI5: Java/J2EE,Microserices,SpringBoot,Node JS, | EJ5: Java/J2EE,Spring Boot | EK5: Java/J2EE,Spring Boot, Microservices | EL5: Mobile Automation | EM5: Mobile automation testing | EN5: Mobility | EO5: MS Power BI Developer | EP5: MSSQL,SQL | EQ5: Mysql | ER5: NET Core,Spring Boot,Microservices | ES5: Networking | ET5: Node JS | EU5: Oracle BRM Testing | EV5: PL SQL Developer | EW5: PL/SQL | EX5: PLSQL Develop, Informatica and Control – M | EY5: PLSQL Developer, Informatica and Control – M | EZ5: PM | FA5: Power BI | FB5: Product designer | FC5: Product Manager | FD5: Project Manager | FE5: Project Manager with Java/Android | FF5: Python,Linux | FG5: Python,Selenium, Robot Framework | FH5: Python,Selenium,API | FI5: Python/C#, Selenium | FJ5: QA , Manual tester role | FK5: RPA Developer | FL5: SDET | FM5: Selenium,Appium | FN5: Senior Java Developer | FO5: SQL,Stored procedures,t-sql | FP5: Testing | FQ5: UI Developer | FR5: UI Developer ,Angular | FS5: UI/UX | FT5: UI/UX role | FU5: Vulnerability | FV5: Windows Install Shield Developer | FX5: Dotnet Core | FZ5: Java | GA5: Java Developer | GB5: JAVA FULL STACK DEVELOPER | GD5: Plsql developer | GF5: DW/EBI | GG5: Power BI | GI5: .Dot Net,Mvc,Sql | GJ5: .Net Core,Angular | GK5: Dotnet Developer | GL5: Mobility | GM5: PM | GN5: UI/UX Designer | GP5: DOTNET | GR5: Dotnet Core | GT5: Dotnet Core | GU5: Plsql developer | GV5: Selenium SDET | GX5: Cyber Security | GZ5: Java | HB5: DOTNET | HC5: SDET | HE5: C,C++ | HF5: Devops Engineer | HG5: Java,Springboot, kafka | HH5: Product Manager | HI5: Python,Selenium,Robot Framework | HK5: PL/SQL | HL5: PLSQL Dev | HM5: Plsql developer | HO5: PT | HQ5: Java | HS5: .Net Core,Angular | HT5: C#.NET,.NET Core,Web API,,Web Services | HU5: Data Scientist Python | HV5: Dell Boomi,API Gateway,B2B/EDI | HW5: Product Manager Jira | HX5: SDETAutomation & Manual Testing, | HZ5: Java,Selenium,API | IA5: Product Manager with Mobile, Web | IB5: Project Manager | IC5: python | ID5: SDET | IE5: SDET | IG5: Cyber Security | IH5: UI/UX | IJ5: SDET | IL5: Dotnet Core | IM5: Java | IO5: 2-5y C#, Selenium with API Testing | IP5: 4y+ Mobile and Web application Automation | IQ5: 4y+ Mobile and Web application Automation testing | IR5: 5y Project Manager with Release Management and ITIL | IS5: 8-12y5-8y Developer | IU5: .net core | IV5: .Net Core,Angular | IW5: 2-5y Windows Install Shield Developer | IX5: 4y+ Andriod Developer with Flutter | IY5: 4y+ iOS Developer | IZ5: 4y+ Java/J2EE,Microserices,SpringBoot,Node JS | JA5: 5-8y Java/.NET,Selenium,eCommerce Domain | JB5: 5-8y Java/J2EE,Spring Boot,Hibernate,Restful Services,JUnit | JC5: 5-8y Java/J2EE,Spring Boot,Hibernate,Restful Services,Junit - | JD5: 8-10y Project Manager with Cloud-Native Apps and Devops Experience | JE5: Andriod Developer with Flutter | JF5: Android Developer | JG5: Asp.Net MVC, Entity Framework,Web api | JH5: BRM | JI5: C#.NET,.NET Core, Web API, MVC,Angular,Jquery role . | JJ5: C,C++ | JK5: C/C++ | JL5: Cyber Security | JM5: Cybersecurity | JN5: Dell Boomi | JO5: Dot Net | JP5: DOTNET | JQ5: iOS | JR5: Java | JS5: Java Developer | JT5: Java,Nodejs | JU5: Java,Springboot | JV5: Kafka | JW5: Linux | JX5: Manual and Automation Testing ,Server Hardware Testing | JY5: Mobile Automation | JZ5: Mobile automation testing | KA5: MongoDB | KB5: NET Core,Spring Boot,Microservices | KC5: Node JS | KD5: PL SQL Dev | KE5: PL/SQL | KF5: Plsql developer | KG5: PM | KH5: Power BI | KI5: Product Manager | KJ5: Product Manager with Mobile, Web | KK5: Project Manager | KL5: Project Manager | KM5: Project Manager ,SDLC,AGILE | KN5: Project Manager with Java/Android | KO5: Project manager with release mngt ITIL | KP5: python | KQ5: QA , Manual tester role | KR5: QA , Manual tester role:- | KS5: RPA Developer | KT5: RPA, Automation Anywhere,UiPath | KU5: SDET | KV5: SDET - Automation Testing,Selenium,Appium,Java | KW5: Selenium SDET | KX5: Selenium,Appium | KY5: Server | KZ5: SQL,Stored procedures,t-sql | LA5: Technical Project Manager | LB5: UI | LC5: UI Developer | LD5: UI Developer ,Angular | LE5: UI/UX | LF5: UI/UX Designer | LG5: Vulnerability | LH5: Windows Install Shield Developer | LJ5: .net core | LK5: Java | LL5: SDET | LN5: Java,Selenium | LP5: .net | LQ5: .net core | LR5: .Net Core; Angular | LS5: .NET Developer | LT5: 3y SW Automation Testing,Python-Robot Framework or C#-Selenium | LU5: 8-12y Full Stack Testing,Automation Testing,UX/API Layer,SQL | LV5: 8y+ Java,IBM MDM Tool - IBM Infosphere,PLSQL | LW5: Adobe Experience Manager | LX5: ANGULAR, NODE JS,TYPE SCRIPT | LY5: Boomi | LZ5: Boomi,Javascript | MA5: C#, Dot Net (5-8 Yrs) | MB5: C#, Selenium with API testing | MC5: C#, Selenium with API Testing | MD5: C#, Selenium, API Testing | ME5: C#.NET Core, Angular | MF5: C#.NET,.NET Core,MVC,REST API/Web APIs,JavaScript/JQuery/AJAX/Bootstrap,SQL Server,CI-CD pipeline | MG5: Data Science | MH5: Data Scientist | MI5: Devops,Docker,Kubernete,Linux | MJ5: Dot Net | MK5: DOTNET | ML5: Dotnet Core | MM5: DW/EBI | MN5: Governance,Risk Management,Compliance | MO5: GPU Driver Engineer | MP5: Hadoop developer | MQ5: iMobile Developer with iOS Developer | MR5: Informatica power center | MS5: Infrastructure Engineer | MT5: IT Secruity | MU5: It Security | MV5: Java | MW5: Java Backend developer | MX5: Java Developer | MY5: Java Selenium | MZ5: JAVA/J2EE | NA5: Java/J2EE | NB5: Java/J2EE,Microserices,SpringBoot,Node JS | NC5: Junior DW/EBI | ND5: Mobile Automation | NE5: MongoDB | NF5: Node JS | NG5: Oracle PLSQL with ORACLE EBS | NH5: Oracle SOA | NI5: PLSQL Dev | NJ5: PM | NK5: Power BI | NL5: Power shell | NM5: Powershell | NN5: Product Manager | NO5: Project Manager | NP5: python | NQ5: Python,Selenium,API | NR5: RPA | NS5: RPA Developer | NT5: SDET | NU5: Selenium SDET | NV5: Senior DW/EBI | NW5: Tableau | NX5: UAT Automation | NY5: UI | NZ5: UI +AngularJS Developer | OA5: UI Developer | OB5: UI/UX(Node.js,typescript,Angular) | OC5: Unit Testing | OD5: UX Designer | OE5: Windows Installer | OG5: C#, DotNet (8 -12 Yrs) | OI5: DW/EBI | OJ5: ELK | OK5: I Mobile& IOS Developer | OL5: iOS | ON5: DevOps | OO5: DW/EBI | OP5: Java Developer | OQ5: Mobility | OR5: Node + Angular developer | OS5: PM | OT5: Product Manager | OU5: SDET | OV5: Selenium,Appium,Java | OW5: Tandem | OX5: UI/UX | OZ5: IOS Developer | PA5: Java | PB5: Java Fullstack Developer | PC5: Oracle BRM Testing | PD5: SDET | PF5: DevOps | PG5: Java/J2EE,Spring Boot | PI5: Java/J2EE,Spring Boot, Elastic search- | PJ5: .net core | PK5: .Net Core Full Stack | PL5: .Net Core,Angular | PM5: .Net Fullstack | PN5: .NET,SQL,WEB API | PO5: .Netcore | PP5: Ansible,GitLab,Jenkins | PQ5: Automation Engineer - SDET | PR5: C# .Net, .NET Core, Web Api, Angular | PS5: C#.NET, Windows internals, Desktop application | PT5: C#/Java,Selenium | PU5: Cyber Security | PV5: Data Scientist | PW5: DevOps | PX5: Dot Net | PY5: DOTNET | PZ5: Hadoop developer | QA5: IOS Developer | QB5: iOS Develper | QC5: Java | QD5: Java Developer | QE5: Java,Selenium | QF5: Java,Selenium,API | QG5: Java,Selenium,Automation | QH5: Plsql developer | QI5: PM | QJ5: Powershell | QK5: Product Manager | QL5: Project Manager | QM5: RPA | QN5: SDET | QO5: Selenium SDET | QP5: SW Automation Testing | QQ5: Vulnerability | QS5: Java/J2EE,Spring Boot,Hibernate,Restful Services,JUnit | QT5: .net | QU5: .Net Core,Angular | QV5: .Net Developer | QW5: .NET,SQL,WEB API | QX5: 5-8y Java/.NET,Selenium,eCommerce Domain | QY5: 5-8y Java/J2EE,Spring Boot,Hibernate,Restful Services,JUnit | QZ5: C#,Selenium | RA5: Dot Net | RB5: DOTNET | RC5: iOS | RD5: IOS Developer | RE5: Java | RF5: JAVA , Strong exp in spring boot | RG5: Java Developer | RH5: Java Selenium | RI5: Java, Spring, Springboot | RJ5: Java, Springboot, Microservices, Kafka MongoDB | RK5: Java,Selenium | RL5: Java,Selenium,API | RM5: Java,Selenium,API | RN5: java,selenium,API testing | RO5: Java,Springboot | RP5: Java/J2EE,Core Java | RQ5: Java/J2EE,Spring Boot, React | RR5: java/J2EE,Spring Boot,Hibernate,Restful Services,JUnit | RS5: Python,Selenium,API | RT5: SDET | RU5: UI Developer | RV5: UI Developer ,Angular | RW5: UI/UX | RX5: Windows Install Shield Developer | RZ5: .Net Core,Angular | SA5: .NET,SQL,WEB API | SB5: Java | SC5: Java,Selenium,API | SD5: UI Developer | SE5: UI Developer ,Angular | SF5: UI Developer with Typescript,Angular,Angular JS,React JS | SG5: UI/UX | SI5: .Net Core,Angular | SJ5: .NET Core,Spring Boot,Microservices,Kafka | SK5: 5-8y Java/J2EE,Spring Boot,Hibernate,Restful Services,Junit - | SL5: DOTNET | SM5: Java | SO5: C#, DotNet | SQ5: .NET Developer | SR5: .NET Full Stack Developer | SS5: C#, .NET,.NET Core,MVC,REST API OR Web APIs, JavaScript | ST5: C#, DotNet (5-8 Yrs) | SU5: C#, Selenium, API Testing | SV5: Dot Net | SW5: DOTNET | SX5: Informatica Power center , writing SQL queries | SY5: Java Selenium | SZ5: SDET | TA5: (blank)
B6: Febha John | AH6: 1 | AJ6: 1 | AM6: 2 | AP6: 1 | AQ6: 2 | AR6: 2 | AU6: 2 | AY6: 1 | BA6: 12 | BB6: 3 | BC6: 2 | BD6: 1 | BF6: 2 | BH6: 2 | BN6: 2 | BR6: 1 | BT6: 1 | BU6: 1 | BV6: 5 | BW6: 1 | BY6: 1 | CB6: 3 | CC6: 4 | CD6: 3 | CE6: 2 | CF6: 2 | CG6: 1 | CH6: 1 | CJ6: 2 | CK6: 1 | CL6: 2 | CP6: 43 | CQ6: 2 | CR6: 8 | CS6: 1 | CT6: 2 | CU6: 1 | CV6: 3 | CW6: 3 | CX6: 1 | CY6: 1 | CZ6: 1 | DA6: 5 | DB6: 1 | DC6: 2 | DD6: 3 | DE6: 4 | DF6: 1 | DG6: 1 | DN6: 2 | DO6: 5 | DP6: 1 | DQ6: 13 | DR6: 6 | DS6: 3 | DT6: 3 | DU6: 4 | DV6: 1 | DW6: 21 | DX6: 4 | DY6: 4 | DZ6: 4 | EB6: 1 | EC6: 1 | ED6: 8 | EE6: 5 | EF6: 5 | EG6: 3 | EH6: 4 | EI6: 1 | EJ6: 1 | EK6: 1 | EL6: 4 | EM6: 1 | EN6: 5 | EO6: 4 | EP6: 3 | EQ6: 2 | ER6: 3 | ES6: 4 | ET6: 1 | EU6: 1 | EZ6: 3 | FA6: 1 | FB6: 4 | FC6: 3 | FD6: 2 | FE6: 1 | FF6: 3 | FG6: 2 | FI6: 2 | FK6: 1 | FL6: 9 | FM6: 1 | FP6: 7 | FQ6: 6 | FR6: 9 | FS6: 1 | FU6: 2 | FV6: 4 | FW6: 230 | GI6: 1 | GJ6: 1 | GK6: 1 | GL6: 1 | GM6: 1 | GN6: 1 | GO6: 6 | HE6: 2 | HG6: 1 | HH6: 3 | HI6: 3 | HJ6: 9 | IP6: 3 | IQ6: 4 | IR6: 2 | IS6: 2 | IT6: 11 | IV6: 2 | IW6: 2 | IX6: 2 | IY6: 2 | IZ6: 1 | JA6: 1 | JB6: 1 | JC6: 2 | JD6: 5 | JE6: 1 | JF6: 1 | JH6: 5 | JJ6: 1 | JO6: 1 | JQ6: 1 | JR6: 8 | JS6: 3 | JT6: 1 | JU6: 2 | JW6: 1 | JX6: 2 | JY6: 4 | JZ6: 2 | KB6: 1 | KC6: 1 | KG6: 8 | KH6: 1 | KI6: 3 | KK6: 2 | KL6: 2 | KM6: 5 | KN6: 2 | KO6: 3 | KS6: 3 | KT6: 2 | KU6: 1 | KV6: 1 | KX6: 1 | LA6: 4 | LC6: 1 | LD6: 1 | LE6: 2 | LF6: 1 | LH6: 1 | LI6: 97 | LT6: 4 | NB6: 2 | ND6: 3 | NF6: 2 | OE6: 2 | OF6: 13 | OO6: 3 | OP6: 1 | OQ6: 3 | OU6: 4 | OV6: 4 | OY6: 15 | PB6: 1 | PC6: 1 | PE6: 2 | PF6: 2 | PG6: 1 | PH6: 3 | PI6: 2 | PP6: 2 | PR6: 1 | PW6: 2 | PX6: 1 | PY6: 1 | QA6: 1 | QB6: 2 | QC6: 1 | QD6: 1 | QN6: 2 | QP6: 2 | QR6: 18 | QS6: 1 | QT6: 1 | QU6: 5 | QV6: 1 | QW6: 2 | QX6: 1 | QY6: 1 | RB6: 5 | RC6: 4 | RD6: 3 | RE6: 10 | RF6: 1 | RG6: 4 | RI6: 1 | RJ6: 1 | RK6: 8 | RL6: 25 | RM6: 3 | RN6: 1 | RO6: 2 | RQ6: 1 | RR6: 1 | RS6: 2 | RT6: 8 | RU6: 2 | RV6: 5 | RW6: 1 | RX6: 8 | RY6: 108 | RZ6: 1 | SB6: 1 | SC6: 1 | SD6: 1 | SE6: 1 | SF6: 1 | SG6: 1 | SH6: 7 | SI6: 1 | SJ6: 1 | SK6: 1 | SL6: 1 | SM6: 1 | SN6: 5 | SR6: 1 | SX6: 2 | SY6: 1 | TB6: 4 | TC6: 583
B7: Pratik Yamawar | AD7: 2 | AE7: 2 | AF7: 1 | AG7: 1 | AI7: 1 | AK7: 1 | AL7: 1 | AN7: 1 | AO7: 2 | AQ7: 1 | AS7: 4 | AT7: 2 | AV7: 4 | AW7: 1 | AX7: 4 | AZ7: 1 | BA7: 25 | BB7: 6 | BE7: 1 | BG7: 2 | BI7: 1 | BJ7: 2 | BK7: 2 | BL7: 3 | BM7: 1 | BO7: 5 | BP7: 3 | BQ7: 2 | BR7: 1 | BS7: 2 | BV7: 2 | BX7: 1 | BZ7: 1 | CA7: 1 | CC7: 11 | CI7: 2 | CM7: 20 | CN7: 4 | CO7: 1 | CP7: 74 | CR7: 1 | DH7: 3 | DI7: 1 | DJ7: 1 | DK7: 2 | DL7: 4 | DM7: 1 | DQ7: 1 | EA7: 1 | EE7: 1 | EV7: 3 | EW7: 3 | EX7: 3 | EY7: 2 | FC7: 2 | FD7: 1 | FH7: 5 | FJ7: 1 | FL7: 1 | FO7: 6 | FT7: 2 | FW7: 45 | GP7: 2 | GQ7: 2 | HB7: 1 | HC7: 1 | HD7: 2 | HS7: 1 | HY7: 1 | HZ7: 7 | IA7: 1 | IB7: 1 | IC7: 2 | ID7: 2 | IE7: 1 | IF7: 14 | IO7: 4 | IT7: 4 | IV7: 1 | JG7: 2 | JI7: 1 | JK7: 1 | JN7: 2 | JO7: 9 | JP7: 1 | JR7: 1 | KI7: 1 | KJ7: 1 | KQ7: 1 | KR7: 1 | KZ7: 3 | LI7: 25 | LP7: 1 | LQ7: 8 | LR7: 4 | LX7: 1 | LY7: 2 | LZ7: 3 | MA7: 4 | MB7: 6 | MC7: 6 | MD7: 12 | ME7: 4 | MF7: 1 | MG7: 2 | MH7: 2 | MI7: 3 | MJ7: 3 | MK7: 9 | ML7: 1 | MM7: 2 | MO7: 6 | MY7: 1 | NM7: 4 | NN7: 3 | NO7: 2 | NQ7: 2 | NT7: 19 | OB7: 1 | OD7: 2 | OF7: 114 | OG7: 2 | OH7: 2 | ON7: 1 | OR7: 1 | OW7: 2 | OX7: 1 | OY7: 5 | PD7: 1 | PE7: 1 | PJ7: 4 | PK7: 2 | PL7: 6 | PN7: 4 | PS7: 1 | PX7: 1 | PY7: 1 | QF7: 1 | QN7: 3 | QR7: 23 | QT7: 1 | QU7: 1 | QW7: 2 | QZ7: 2 | RA7: 2 | RB7: 2 | RH7: 1 | RM7: 4 | RP7: 1 | RS7: 4 | RT7: 1 | RY7: 21 | SA7: 1 | SH7: 1 | SO7: 1 | SP7: 1 | SS7: 5 | ST7: 11 | SU7: 5 | SV7: 4 | SW7: 2 | SZ7: 4 | TA7: 5 | TB7: 36 | TC7: 398
B8: Vinay Nambiar | C8: 2 | D8: 4 | E8: 2 | F8: 1 | G8: 2 | H8: 12 | I8: 1 | J8: 1 | K8: 3 | L8: 9 | M8: 3 | N8: 21 | O8: 2 | P8: 11 | Q8: 3 | R8: 7 | S8: 3 | T8: 3 | U8: 2 | V8: 1 | W8: 3 | X8: 6 | Y8: 102 | Z8: 1 | AA8: 2 | AB8: 2 | AC8: 5 | DO8: 4 | DW8: 5 | DZ8: 1 | FN8: 1 | FW8: 11 | FX8: 1 | FY8: 1 | FZ8: 1 | GA8: 2 | GB8: 3 | GC8: 6 | GD8: 1 | GE8: 1 | GF8: 5 | GG8: 7 | GH8: 12 | GR8: 1 | GS8: 1 | GT8: 1 | GU8: 2 | GV8: 1 | GW8: 4 | GX8: 1 | GY8: 1 | GZ8: 4 | HA8: 4 | HF8: 2 | HJ8: 2 | HK8: 4 | HL8: 3 | HM8: 8 | HN8: 15 | HO8: 5 | HP8: 5 | HQ8: 1 | HR8: 1 | HT8: 1 | HU8: 1 | HV8: 1 | HW8: 1 | HX8: 1 | HY8: 5 | IG8: 1 | IH8: 2 | II8: 3 | IJ8: 2 | IK8: 2 | IL8: 8 | IM8: 6 | IN8: 14 | IU8: 2 | JL8: 2 | JM8: 2 | JP8: 2 | JR8: 11 | JS8: 3 | JV8: 2 | KD8: 2 | KE8: 2 | KF8: 3 | KG8: 2 | KI8: 3 | KK8: 6 | KP8: 1 | KU8: 4 | KW8: 3 | KY8: 1 | LB8: 2 | LE8: 9 | LI8: 62 | LJ8: 2 | LK8: 1 | LL8: 2 | LM8: 5 | LN8: 2 | LO8: 2 | LP8: 4 | LQ8: 6 | LS8: 6 | LU8: 3 | LV8: 1 | MH8: 7 | MJ8: 2 | MK8: 11 | MM8: 3 | MP8: 2 | MR8: 3 | MS8: 2 | MT8: 4 | MU8: 5 | MV8: 7 | MW8: 4 | MX8: 3 | NC8: 4 | NG8: 2 | NI8: 4 | NJ8: 2 | NK8: 3 | NL8: 3 | NM8: 4 | NN8: 3 | NP8: 2 | NR8: 4 | NS8: 4 | NT8: 14 | NU8: 1 | NV8: 1 | NW8: 3 | NX8: 2 | NY8: 1 | OA8: 2 | OF8: 132 | PA8: 1 | PE8: 1 | PJ8: 11 | PM8: 2 | PO8: 6 | PQ8: 7 | PT8: 2 | PU8: 1 | PX8: 2 | PZ8: 4 | QC8: 2 | QE8: 2 | QG8: 1 | QH8: 2 | QI8: 2 | QL8: 3 | QM8: 5 | QN8: 6 | QO8: 1 | QR8: 59 | SQ8: 1 | TB8: 1 | TC8: 457
B9: (blank)
B10: Divakara Rangaswamy | KA10: 1 | LG10: 1 | LI10: 2 | MN10: 1 | NE10: 2 | NH10: 5 | OC10: 3 | OF10: 11 | OI10: 4 | OJ10: 1 | OK10: 2 | OL10: 1 | OM10: 8 | OS10: 5 | OT10: 1 | OY10: 6 | PV10: 2 | PY10: 1 | QD10: 3 | QJ10: 2 | QK10: 1 | QQ10: 1 | QR10: 10 | TC10: 37
B11: Dinesh Shiranpel | LW11: 8 | MQ11: 33 | MZ11: 8 | NA11: 1 | NN11: 4 | NZ11: 5 | OF11: 59 | OZ11: 1 | PE11: 1 | TC11: 60
B12: Grand Total | C12: 2 | D12: 4 | E12: 2 | F12: 1 | G12: 2 | H12: 12 | I12: 1 | J12: 1 | K12: 3 | L12: 9 | M12: 3 | N12: 21 | O12: 2 | P12: 11 | Q12: 3 | R12: 7 | S12: 3 | T12: 3 | U12: 2 | V12: 1 | W12: 3 | X12: 6 | Y12: 102 | Z12: 1 | AA12: 2 | AB12: 2 | AC12: 5 | AD12: 2 | AE12: 2 | AF12: 1 | AG12: 1 | AH12: 1 | AI12: 1 | AJ12: 1 | AK12: 1 | AL12: 1 | AM12: 2 | AN12: 1 | AO12: 2 | AP12: 1 | AQ12: 3 | AR12: 2 | AS12: 4 | AT12: 2 | AU12: 2 | AV12: 4 | AW12: 1 | AX12: 4 | AY12: 1 | AZ12: 1 | BA12: 37 | BB12: 9 | BC12: 2 | BD12: 1 | BE12: 1 | BF12: 2 | BG12: 2 | BH12: 2 | BI12: 1 | BJ12: 2 | BK12: 2 | BL12: 3 | BM12: 1 | BN12: 2 | BO12: 5 | BP12: 3 | BQ12: 2 | BR12: 2 | BS12: 2 | BT12: 1 | BU12: 1 | BV12: 7 | BW12: 1 | BX12: 1 | BY12: 1 | BZ12: 1 | CA12: 1 | CB12: 3 | CC12: 15 | CD12: 3 | CE12: 2 | CF12: 2 | CG12: 1 | CH12: 1 | CI12: 2 | CJ12: 2 | CK12: 1 | CL12: 2 | CM12: 20 | CN12: 4 | CO12: 1 | CP12: 117 | CQ12: 2 | CR12: 9 | CS12: 1 | CT12: 2 | CU12: 1 | CV12: 3 | CW12: 3 | CX12: 1 | CY12: 1 | CZ12: 1 | DA12: 5 | DB12: 1 | DC12: 2 | DD12: 3 | DE12: 4 | DF12: 1 | DG12: 1 | DH12: 3 | DI12: 1 | DJ12: 1 | DK12: 2 | DL12: 4 | DM12: 1 | DN12: 2 | DO12: 9 | DP12: 1 | DQ12: 14 | DR12: 6 | DS12: 3 | DT12: 3 | DU12: 4 | DV12: 1 | DW12: 26 | DX12: 4 | DY12: 4 | DZ12: 5 | EA12: 1 | EB12: 1 | EC12: 1 | ED12: 8 | EE12: 6 | EF12: 5 | EG12: 3 | EH12: 4 | EI12: 1 | EJ12: 1 | EK12: 1 | EL12: 4 | EM12: 1 | EN12: 5 | EO12: 4 | EP12: 3 | EQ12: 2 | ER12: 3 | ES12: 4 | ET12: 1 | EU12: 1 | EV12: 3 | EW12: 3 | EX12: 3 | EY12: 2 | EZ12: 3 | FA12: 1 | FB12: 4 | FC12: 5 | FD12: 3 | FE12: 1 | FF12: 3 | FG12: 2 | FH12: 5 | FI12: 2 | FJ12: 1 | FK12: 1 | FL12: 10 | FM12: 1 | FN12: 1 | FO12: 6 | FP12: 7 | FQ12: 6 | FR12: 9 | FS12: 1 | FT12: 2 | FU12: 2 | FV12: 4 | FW12: 286 | FX12: 1 | FY12: 1 | FZ12: 1 | GA12: 2 | GB12: 3 | GC12: 6 | GD12: 1 | GE12: 1 | GF12: 5 | GG12: 7 | GH12: 12 | GI12: 1 | GJ12: 1 | GK12: 1 | GL12: 1 | GM12: 1 | GN12: 1 | GO12: 6 | GP12: 2 | GQ12: 2 | GR12: 1 | GS12: 1 | GT12: 1 | GU12: 2 | GV12: 1 | GW12: 4 | GX12: 1 | GY12: 1 | GZ12: 4 | HA12: 4 | HB12: 1 | HC12: 1 | HD12: 2 | HE12: 2 | HF12: 2 | HG12: 1 | HH12: 3 | HI12: 3 | HJ12: 11 | HK12: 4 | HL12: 3 | HM12: 8 | HN12: 15 | HO12: 5 | HP12: 5 | HQ12: 1 | HR12: 1 | HS12: 1 | HT12: 1 | HU12: 1 | HV12: 1 | HW12: 1 | HX12: 1 | HY12: 6 | HZ12: 7 | IA12: 1 | IB12: 1 | IC12: 2 | ID12: 2 | IE12: 1 | IF12: 14 | IG12: 1 | IH12: 2 | II12: 3 | IJ12: 2 | IK12: 2 | IL12: 8 | IM12: 6 | IN12: 14 | IO12: 4 | IP12: 3 | IQ12: 4 | IR12: 2 | IS12: 2 | IT12: 15 | IU12: 2 | IV12: 3 | IW12: 2 | IX12: 2 | IY12: 2 | IZ12: 1 | JA12: 1 | JB12: 1 | JC12: 2 | JD12: 5 | JE12: 1 | JF12: 1 | JG12: 2 | JH12: 5 | JI12: 1 | JJ12: 1 | JK12: 1 | JL12: 2 | JM12: 2 | JN12: 2 | JO12: 10 | JP12: 3 | JQ12: 1 | JR12: 20 | JS12: 6 | JT12: 1 | JU12: 2 | JV12: 2 | JW12: 1 | JX12: 2 | JY12: 4 | JZ12: 2 | KA12: 1 | KB12: 1 | KC12: 1 | KD12: 2 | KE12: 2 | KF12: 3 | KG12: 10 | KH12: 1 | KI12: 7 | KJ12: 1 | KK12: 8 | KL12: 2 | KM12: 5 | KN12: 2 | KO12: 3 | KP12: 1 | KQ12: 1 | KR12: 1 | KS12: 3 | KT12: 2 | KU12: 5 | KV12: 1 | KW12: 3 | KX12: 1 | KY12: 1 | KZ12: 3 | LA12: 4 | LB12: 2 | LC12: 1 | LD12: 1 | LE12: 11 | LF12: 1 | LG12: 1 | LH12: 1 | LI12: 186 | LJ12: 2 | LK12: 1 | LL12: 2 | LM12: 5 | LN12: 2 | LO12: 2 | LP12: 5 | LQ12: 14 | LR12: 4 | LS12: 6 | LT12: 4 | LU12: 3 | LV12: 1 | LW12: 8 | LX12: 1 | LY12: 2 | LZ12: 3 | MA12: 4 | MB12: 6 | MC12: 6 | MD12: 12 | ME12: 4 | MF12: 1 | MG12: 2 | MH12: 9 | MI12: 3 | MJ12: 5 | MK12: 20 | ML12: 1 | MM12: 5 | MN12: 1 | MO12: 6 | MP12: 2 | MQ12: 33 | MR12: 3 | MS12: 2 | MT12: 4 | MU12: 5 | MV12: 7 | MW12: 4 | MX12: 3 | MY12: 1 | MZ12: 8 | NA12: 1 | NB12: 2 | NC12: 4 | ND12: 3 | NE12: 2 | NF12: 2 | NG12: 2 | NH12: 5 | NI12: 4 | NJ12: 2 | NK12: 3 | NL12: 3 | NM12: 8 | NN12: 10 | NO12: 2 | NP12: 2 | NQ12: 2 | NR12: 4 | NS12: 4 | NT12: 33 | NU12: 1 | NV12: 1 | NW12: 3 | NX12: 2 | NY12: 1 | NZ12: 5 | OA12: 2 | OB12: 1 | OC12: 3 | OD12: 2 | OE12: 2 | OF12: 329 | OG12: 2 | OH12: 2 | OI12: 4 | OJ12: 1 | OK12: 2 | OL12: 1 | OM12: 8 | ON12: 1 | OO12: 3 | OP12: 1 | OQ12: 3 | OR12: 1 | OS12: 5 | OT12: 1 | OU12: 4 | OV12: 4 | OW12: 2 | OX12: 1 | OY12: 26 | OZ12: 1 | PA12: 1 | PB12: 1 | PC12: 1 | PD12: 1 | PE12: 5 | PF12: 2 | PG12: 1 | PH12: 3 | PI12: 2 | PJ12: 15 | PK12: 2 | PL12: 6 | PM12: 2 | PN12: 4 | PO12: 6 | PP12: 2 | PQ12: 7 | PR12: 1 | PS12: 1 | PT12: 2 | PU12: 1 | PV12: 2 | PW12: 2 | PX12: 4 | PY12: 3 | PZ12: 4 | QA12: 1 | QB12: 2 | QC12: 3 | QD12: 4 | QE12: 2 | QF12: 1 | QG12: 1 | QH12: 2 | QI12: 2 | QJ12: 2 | QK12: 1 | QL12: 3 | QM12: 5 | QN12: 11 | QO12: 1 | QP12: 2 | QQ12: 1 | QR12: 110 | QS12: 1 | QT12: 2 | QU12: 6 | QV12: 1 | QW12: 4 | QX12: 1 | QY12: 1 | QZ12: 2 | RA12: 2 | RB12: 7 | RC12: 4 | RD12: 3 | RE12: 10 | RF12: 1 | RG12: 4 | RH12: 1 | RI12: 1 | RJ12: 1 | RK12: 8 | RL12: 25 | RM12: 7 | RN12: 1 | RO12: 2 | RP12: 1 | RQ12: 1 | RR12: 1 | RS12: 6 | RT12: 9 | RU12: 2 | RV12: 5 | RW12: 1 | RX12: 8 | RY12: 129 | RZ12: 1 | SA12: 1 | SB12: 1 | SC12: 1 | SD12: 1 | SE12: 1 | SF12: 1 | SG12: 1 | SH12: 8 | SI12: 1 | SJ12: 1 | SK12: 1 | SL12: 1 | SM12: 1 | SN12: 5 | SO12: 1 | SP12: 1 | SQ12: 1 | SR12: 1 | SS12: 5 | ST12: 11 | SU12: 5 | SV12: 4 | SW12: 2 | SX12: 2 | SY12: 1 | SZ12: 4 | TA12: 5 | TB12: 41 | TC12: 1535

Sheet Candidate Basedata
A1: Sl No | B1: Account | C1: Profile Submission Date | D1: SO Number | E1: Recruiter Name | G1: Source | H1: Sub Source | I1: Mandatory Skill | J1: Skill combinations | K1: Candidate Status | L1: Detailed Status | M1: Hire Type | N1: Candidate ID | O1: Candidate Name | P1: Contact Number | Q1: Email id | R1: Total Yrs of Exp | S1: Relevant Exp | T1: Current Company | U1: Current CTC | V1: Expected CTC | W1: Notice period | X1: Buyout(Y/N) | Y1: Ex-Employee(Y/N) | Z1: If Rehire Ex- Employee ID | AA1: Current Location | AB1: Preferred Location | AC1: Remarks
A2: 1 | B2: Dell FG | C2: 44546 | D2: 38024355 | E2: Rahul Kapoor | F2: U82721 | G2: Vendor Partner | H2: Mindsoft | I2: Java Selenium | J2: JAVA SELENIUM | K2: Dropped | M2: Regular | N2: 484611 | O2: Jacob | P2: 9553801682 | Q2: jacobkoheer@gmail.com | R2: 3yrs | S2: 2yrs | T2: Sun icon | U2: 600000 | V2: 950000 | W2: LWD-Dec 22nd-Immediate | X2: N | Y2: N | Z2: N | AA2: Hyderabad | AB2: Banglore/Hyderabad
A3: 2 | B3: Dell FG | C3: 44550 | D3: 38024355 | E3: Rahul Kapoor | F3: U82721 | G3: Vendor Partner | H3: Mindsoft | I3: SDET | J3: JAVA SELENIUM | K3: Tech1 Reject | L3: Screening IP | M3: Regular | N3: 351671 | O3: T M NANDINI | P3: 9739829708 | Q3: nandini.m.t78@gmail.com | R3: 3.4yrs | S3: 3.4yrs | T3: Mindtree | U3: 550000 | V3: 1150000 | W3: LWD-JAN 25TH | X3: N | Y3: N | Z3: N | AA3: Bangalore | AB3: Bangalore
A4: 3 | B4: Dell FG | C4: 44550 | D4: 94967553 | E4: Rahul Kapoor | F4: U82721 | G4: UST Global | H4: Mindsoft | I4: QA , Manual tester role | J4: SDET | K4: Joined | L4: Rejected | M4: Regular | N4: 354205 | O4: Vaishali Dixit | P4: 9691520066 | Q4: dixit.vaishali08@gmail.com | R4: 3.5yrs | S4: 3yrs | T4: Capgemini | U4: 450000 | V4: 1300000 | W4: 30 days(LWD: 26th Jan) | X4: N | Y4: N | Z4: NA | AA4: Bangalore | AB4: Bangalore
A5: 4 | B5: Dell FG | C5: 44550 | D5: 31972088 | E5: Vinay Nambiar | F5: 181547 | G5: Vendor Partner | H5: SRS | I5: Java | J5: Java/J2EE,Spring Boot,Spring Core,Spring MVC, Spring Web Services, Spring boot, Spring Data, Spring Cloud,HTML/CSS/JS | K5: Joined | L5: Interview No show | M5: Regular | N5: 419101 | O5: Hema Latha | P5: 9948358570 | Q5: hemalatha.friends@gmail.com | R5: 14 yr | S5: 14 yr | T5: Infosys | U5: 1450000 | V5: 3000000 | W5: LWD : 4/1/2021 | X5: No | Y5: No | Z5: N | AA5: Hyderabad | AB5: Hyderabad
A6: 5 | B6: Dell FG | C6: 44551 | D6: 94967553 | E6: Rahul Kapoor | F6: U82721 | G6: UST Global | H6: Mindsoft | I6: QA , Manual tester role:- | J6: SDET | K6: Joined | L6: Rejected | M6: Regular | N6: 379458 | O6: Alekya | P6: 9441095144 | Q6: alekya.d1988@gmail.com | R6: 4.8yrs | S6: 4.8yrs | T6: Nuance Transcription | U6: 500000 | V6: 850000 | W6: Immediate | X6: N | Y6: N | Z6: NA | AA6: Bangalore | AB6: Bangalore
A7: 6 | B7: Dell FG | C7: 44551 | D7: 82866188 | E7: Rahul Kapoor | F7: U82721 | G7: UST Global | H7: Mindsoft | I7: UI/UX role | J7: UI | K7: Dropped | L7: Drop out | M7: Regular | N7: 355575 | O7: Rajesh Sah | P7: 9739607439 | Q7: codeuix@gmail.com | R7: 6 years | S7: 5Years | T7: Nubewell Networks Pvt Ltd | U7: 1500000 | V7: 2200000 | W7: 11-Jan LWD | X7: N | Y7: N | Z7: NA | AA7: Bangalore | AB7: Bangalore
A8: 7 | B8: Dell FG | C8: 44551 | D8: 82866188 | E8: Rahul Kapoor | F8: U82721 | G8: UST Global | H8: Mindsoft | I8: UI/UX role | J8: UI | K8: Dropped | L8: Drop out | M8: Regular | N8: H8271088 | O8: Ankita Awasthi | P8: 9717348292 | Q8: ankitaawasthi05@gmail.com | R8: 7.6years | S8: 3+years | T8: Genpact | U8: 1000000 | V8: 2400000 | W8: 29-Dec LWD | X8: N | Y8: N | Z8: NA | AA8: Bangalore | AB8: Bangalore
A9: 8 | B9: Dell FG | C9: 44551 | D9: 51907700 | E9: Vinay Nambiar | F9: 181547 | G9: Vendor Partner | H9: SRS | I9: Java | J9: Java/J2EE,Spring Boot,Spring Core,Spring MVC, Spring Web Services, Spring boot, Spring Data, Spring Cloud,HTML/CSS/JS | K9: Joined | L9: Not responding | M9: Regular | N9: H14387 | O9: Sreedhar Vinjamuri | P9: 7337067133 | Q9: sreedhar.vin12@gmail.com | R9: 13 yr | S9: 13 yr | T9: Virinchi Technologies | U9: 1500000 | V9: 2500000 | W9: IMMEDATE JOINNER | X9: No | Y9: No | AA9: Hyderabad | AB9: Hyderabad
A10: 9 | B10: Dell FG | C10: 44551 | D10: 57335575 | E10: Vinay Nambiar | F10: 181547 | G10: Vendor Partner | H10: SRS | I10: Java | J10: Java/J2EE,Spring Boot,Spring Core,Spring MVC, Spring Web Services, Spring boot, Spring Data, Spring Cloud,HTML/CSS/JS | K10: Joined | L10: Interview No show | M10: Regular | N10: 419812 | O10: Pokuri Ramanjaneyulu | P10: 8106332319 | Q10: ram1980.p@gmail.com | R10: 14 yr | S10: 14 yr | T10: HCL Technologies, | U10: 1450000 | V10: 2400000 | W10: LWD: 28/1/2021 | X10: No | Y10: No | AA10: Hyderabad | AB10: Hyderabad
A11: 10 | B11: Dell FG | C11: 44551 | D11: 94990037 | E11: Vinay Nambiar | F11: 181547 | G11: Vendor Partner | H11: SRS | I11: Java | J11: Java/J2EE,Spring Boot,Spring Core,Spring MVC, Spring Web Services, Spring boot, Spring Data, Spring Cloud,HTML/CSS/JS | K11: Joined | L11: Interview No show | M11: Regular | N11: 418251 | O11: Sailaja Malyala | P11: 9848623920 | Q11: sailajamalyal@gmail.com | R11: 14 yr | S11: 14 yr | T11: IBM | U11: 1200000 | V11: 3000000 | W11: ELWD : 26/01/22 | X11: No | Y11: No | AA11: Hyderabad | AB11: Hyderabad
A12: 11 | B12: Dell FG | C12: 44552 | D12: 44173531 | E12: Vinay Nambiar | F12: 181547 | G12: Vendor Partner | H12: SRS | I12: Java | J12: Java/J2EE, Angularjs | K12: Dropped | L12: Not interested | M12: Regular | N12: 421816 | O12: G.Ramana Reddy | P12: 9390911344 | Q12: grreddy1729@gmail.com | R12: 5 Years | S12: 5 Years | T12: L&T Infotech | U12: 900000 | V12: 1500000 | W12: LWD 30-01-2022 | X12: Yes | Y12: No | AA12: Hyderabad | AB12: Hyderabad
A13: 12 | B13: Dell FG | C13: 44552 | D13: 44173531 | E13: Vinay Nambiar | F13: 181547 | G13: Vendor Partner | H13: SRS | I13: Java | J13: Java/J2EE, Angularjs | K13: Screen Reject | L13: Not responding | M13: Regular | N13: 421822 | O13: Prem Kumar Jannu | P13: 7893092220 | Q13: prem.jannu182829@gamil.com | R13: 9 Years | S13: 5 Years | T13: Infosys LTD | U13: 1200000 | V13: 2000000 | W13: LWD 31-01-2022 | X13: Yes | Y13: No | AA13: Hyderabad | AB13: Hyderabad
A14: 13 | B14: Dell FG | C14: 44552 | D14: 67489866 | E14: Vinay Nambiar | F14: 181547 | G14: Vendor Partner | H14: SRS | I14: DevOps | J14: 5-8y Devops with GIT,CICD (Gitlab),Powershell/Bash | K14: Dropped | L14: Requirement closed | M14: Regular | N14: 421830 | O14: Srinivas. Y | P14: 8247858588 | Q14: srinivasyara1257@gmail.com | R14: 5.3years | S14: 3.5years | T14: Sciens Software Technologies | U14: 650000 | V14: 1000000 | W14: 25days | X14: Yes | Y14: No | AA14: Hyderabad | AB14: Hyderabad | AC14: Req closed
A15: 14 | B15: Dell FG | C15: 44553 | D15: 94967553 | E15: Rahul Kapoor | F15: U82721 | G15: UST Global | H15: Mindsoft | I15: QA , Manual tester role | J15: SDET | K15: Dropped | L15: Pending | M15: Regular | N15: 389073 | O15: Vishnu kumar | P15: 9390839924 | Q15: m.vishnu225@gmail.com | R15: 3 yrs | S15: 3 yrs | T15: Brillquest technologies Pvt Ltd | U15: 300000 | V15: 500000 | W15: LWD-3rd Jan 22 | X15: N | Y15: N | Z15: NA | AA15: Bangalore | AB15: Bangalore
A16: 15 | B16: Dell FG | C16: 44553 | D16: 67489866 | E16: Vinay Nambiar | F16: 181547 | G16: Vendor Partner | H16: SRS | I16: DevOps | J16: 5-8y Devops with GIT,CICD (Gitlab),Powershell/Bash | K16: Dropped | L16: Requirement closed | M16: Regular | N16: 421842 | O16: Tejaswi Jonnalagadda | P16: 6302517658 | Q16: tejaswi.jonnalagadda91@gmail.com | R16: 7.2years | S16: 7years | T16: Cognizant | U16: 510000 | V16: 800000 | W16: 30days | X16: Yes | Y16: No | AA16: Hyderabad | AB16: Hyderabad | AC16: Req closed
A17: 16 | B17: Dell FG | C17: 44553 | D17: 98936697 | E17: Vinay Nambiar | F17: 181547 | G17: Vendor Partner | H17: SRS | I17: Java | J17: Java/J2EE,Full Stack Developer,Spring Boot,Angular,Cloud Technologies | K17: Screen Reject | L17: Not responding | M17: Regular | N17: 422936 | O17: Raja Mohan Munjeti | P17: 9492543488 | Q17: mohan123.java@gmail.com | R17: 14 yr | S17: 14 yr | T17: Birlasoft | U17: 1300000 | V17: 2400000 | W17: LWD 20/1/2022 | X17: No | Y17: No | AA17: Hyderabad | AB17: Hyderabad
A18: 17 | B18: Dell FG | C18: 44554 | D18: 34147670 | E18: Rahul Kapoor | F18: U82721 | G18: UST Global | H18: Mindsoft | I18: C#.NET,.NET Core, Web API, MVC,Angular,Jquery role . | J18: C#.NET | K18: Dropped | L18: High ctc expectation | M18: Regular | N18: H7835795 | O18: Venna Bhagyalakshmi | P18: 7022114311 | Q18: Bhagyalaxmi.venna@gmail.com | R18: 5.1 years | S18: 5.1 years | T18: Infosys, | U18: 730000 | V18: 2000000 | W18: 10-Jan LWD | X18: N | Y18: N | Z18: NA | AA18: Bangalore | AB18: Bangalore
A19: 18 | B19: Dell FG | C19: 44554 | D19: 34147670 | E19: Rahul Kapoor | F19: U82721 | G19: UST Global | H19: Mindsoft | I19: C#.NET,.NET Core, Web API, MVC,Angular,Jquery role . | J19: C#.NET | K19: Joined | L19: Rejected | M19: Regular | N19: H6549840 | O19: Swagat Das Pattanaik | P19: 9090016506 | Q19: sdpswagat@gmail.com | R19: 8 years | S19: 8 years | T19: Infosys | U19: 1600000 | V19: 2100000 | W19: 30 Days (in provision period till dec end) | X19: N | Y19: N | Z19: NA | AA19: Bhubaneswar | AB19: Bangalore
A20: 19 | B20: Dell FG | C20: 44554 | D20: 92843512 | E20: Rahul Kapoor | F20: U82721 | G20: UST Global | H20: Mindsoft | I20: C#.NET,.NET Core, Web API, MVC,Angular,Jquery | J20: C#.NET | K20: Dropped | L20: Drop out | M20: Regular | N20: 402046 | O20: Rajat Patel | P20: 8970264977 | Q20: rpatel062021@gmail.com | R20: 7.3yrs | S20: 4yrs | T20: Wipro Limited | U20: 1300000 | V20: 1800000 | W20: 30 days(LWD:27th Jan) | X20: N | Y20: N | Z20: NA | AA20: Bangalore | AB20: Bangalore
A21: 20 | B21: Dell FG | C21: 44554 | D21: 68506880 | E21: Rahul Kapoor | F21: U82721 | G21: UST Global | H21: Mindsoft | I21: C#.NET,.NET Core, Web API, MVC,Angular,Jquery | J21: C#.NET | K21: Dropped | L21: High ctc rejected | M21: Regular | N21: 401907 | O21: Pramod K | P21: 9538686070 | Q21: Pramodk41@gmail.com | R21: 11yrs | S21: 5yrs | T21: Wells Fargo EGS India Pvt. Ltd | U21: 1600000 | V21: 2600000 | W21: 20 days(LWD:14th Jan) | X21: N | Y21: Y | AA21: Bangalore | AB21: Bangalore
A22: 21 | B22: Dell FG | C22: 44554 | D22: 68506880 | E22: Rahul Kapoor | F22: U82721 | G22: UST Global | H22: Mindsoft | I22: C#.NET,.NET Core, Web API, MVC,Angular,Jquery | J22: C#.NET | K22: Dropped | L22: Duplicate | M22: Regular | N22: 402000 | O22: Ramachandra Reddy E | P22: 9739527778 | Q22: ercreddy4@gmail.com | R22: 14.5yrs | S22: 4.5yrs | T22: Not working | U22: 1900000 | V22: 2700000 | W22: Immediate | X22: N | Y22: N | Z22: NA | AA22: Bangalore | AB22: Bangalore
A23: 22 | B23: Dell FG | C23: 44554 | D23: 98936697 | E23: Vinay Nambiar | F23: 181547 | G23: Vendor Partner | H23: SRS | I23: Java | J23: Java/J2EE,Full Stack Developer,Spring Boot,Angular,Cloud Technologies | K23: Screen Reject | L23: Not responding | M23: Regular | N23: H8110634 | O23: Jinka Mohan | P23: 9963120609 | Q23: jinkamohan@yahoo.com | R23: 15 YR | S23: 15 YR | T23: Hyderabad | U23: 1500000 | V23: 1800000 | W23: IMMEDAITE JOINNER | X23: No | Y23: No | AA23: Hyderabad | AB23: Hyderabad
A24: 23 | B24: Dell FG | C24: 44554 | D24: 77765032 | E24: Vinay Nambiar | F24: 181547 | G24: Vendor Partner | H24: SRS | I24: Java | J24: Java/J2EE,Spring,PostgreSQL,ReactJS,PCF,Cloud Microservices,TFS,GitLab,Dev Ops CICD | K24: Screen Reject | L24: Not responding | M24: Regular | N24: 422946 | O24: C. Phani Kishore | P24: 9502329926 | Q24: phanikishorechavvakula@gmail.com | R24: 4.10 years | S24: 4.2 years | T24: Zenith Technology Services | U24: 1000000 | V24: 1400000 | W24: LWD: 17/01/2022 | X24: Yes | Y24: No | AA24: Hyderabad | AB24: Hyderabad
A25: 24 | B25: Dell FG | C25: 44554 | D25: 58270892 | E25: Rahul Kapoor | F25: U82721 | G25: Vendor Partner | H25: Nityo InfoTech | I25: PLSQL Developer, Informatica and Control – M | J25: PLSQL Developer | K25: Dropped | M25: Regular | N25: 431922 | O25: Tanguturi Jayapal | P25: 8217012668/7899098018 | Q25: jayapalinfo232@gmail.com | R25: 3.8 Years | S25: 3.8 Years | T25: Tata Consultancy Services Ltd. | U25: 520000 | V25: 850000 | W25: LWD:30/12/21 | X25: N | Y25: N | Z25: NA | AA25: Bangalore | AB25: Bangalore
A26: 25 | B26: Dell FG | C26: 44557 | D26: 58270892 | E26: Rahul Kapoor | F26: U82721 | G26: Vendor Partner | H26: Nityo InfoTech | I26: PLSQL Developer, Informatica and Control – M | J26: PLSQL Developer | K26: Dropped | M26: Regular | N26: 430273 | O26: Ashok Kumar Nahak | P26: 7550154965 | Q26: ashoktech1008@gmail.com | R26: 3.5 Years | S26: 3.5 Years | T26: PLEXUS SOFTWARE SECURITY SYSTEMS PRIVATE LIMITED | U26: 850000 | V26: 1050000 | W26: Immediate | X26: N | Y26: N | Z26: NA | AA26: Chennai | AB26: Bangalore
A27: 26 | B27: Dell FG | C27: 44557 | D27: 58270892 | E27: Rahul Kapoor | F27: U82721 | G27: Vendor Partner | H27: Nityo InfoTech | I27: PLSQL Develop, Informatica and Control – M | J27: PLSQL Developer | K27: Dropped | M27: Regular | N27: 430286 | O27: M Murali krishna | P27: 8217455947/7008255417 | Q27: medmuralikrishna@gmail.com | R27: 3.6 Years | S27: 3.6 Years | T27: Cognizant Technologies | U27: 850000 | V27: 1050000 | W27: 30days(15days) | X27: N | Y27: N | Z27: NA | AA27: Bangalore | AB27: Bangalore
A28: 27 | B28: Dell FG | C28: 44557 | D28: 58270892 | E28: Rahul Kapoor | F28: U82721 | G28: Vendor Partner | H28: Nityo InfoTech | I28: PLSQL Develop, Informatica and Control – M | J28: PLSQL Developer | K28: Dropped | M28: Regular | N28: 430617 | O28: Eswar Sai S | P28: 7675099160 | Q28: eswarsai.etldb@gmail.com | R28: 3.5 Years | S28: 3 Years | T28: Deltra Soft Technologies Pvt Ltd | U28: 360000 | V28: 650000 | W28: 30days(15days) | X28: Y | Y28: N | Z28: NA | AA28: Hyderabad | AB28: Bangalore
A29: 28 | B29: Dell FG | C29: 44557 | D29: 34147670 | E29: Rahul Kapoor | F29: U82721 | G29: UST Global | H29: Mindsoft | I29: C#.NET,.NET Core, Web API, MVC,Angular,Jquery role | J29: C#.NET | K29: Dropped | L29: Drop out | M29: Regular | N29: L376418 | O29: Manikandan K | P29: 7829098574 | Q29: maniksfwr@gmail.com | R29: 7.2 yrs | S29: 4yrs | T29: Not working | U29: 950000 | V29: 1700000 | W29: Immediate | X29: N | Y29: N | Z29: NA | AA29: Bangalore | AB29: Bangalore
A30: 29 | B30: Dell FG | C30: 44557 | D30: 58270892 | E30: Rahul Kapoor | F30: U82721 | G30: Vendor Partner | H30: Nityo InfoTech | I30: PLSQL Develop, Informatica and Control – M | J30: PLSQL Developer | K30: Dropped | M30: Regular | N30: 431752 | O30: Naga Malleswara Rao Mannem | P30: 7659935955 | Q30: nagamallesh519@gmail.com | R30: 4.6 Years | S30: 4.6 Years | T30: Tata Consultancy Services Ltd. | U30: 600000 | V30: 1050000 | W30: 30days(15days) | X30: N | Y30: N | Z30: NA | AA30: Bangalore | AB30: Bangalore
A31: 30 | B31: Dell FG | C31: 44558 | D31: 67489866 | E31: Vinay Nambiar | F31: 181547 | G31: Vendor Partner | H31: SRS | I31: DevOps | J31: 5-8y Devops with GIT,CICD (Gitlab),Powershell/Bash | K31: Dropped | L31: Requirement closed | M31: Regular | N31: H7890084 | O31: Prashanth Reddy | P31: 7816087160 | Q31: prashanth.anakapally@gmail.com | R31: 5years | S31: 3years | T31: Future Nine Information Technologies Pvt. Ltd | U31: 700000 | V31: 1300000 | W31: 25days | X31: No | Y31: No | AA31: Hyderabad | AB31: Hyderabad
A32: 31 | B32: Dell FG | C32: 44558 | D32: 67489866 | E32: Vinay Nambiar | F32: 181547 | G32: Vendor Partner | H32: SRS | I32: DevOps | J32: 5-8y Devops with GIT,CICD (Gitlab),Powershell/Bash | K32: Dropped | L32: Requirement closed | M32: Regular | N32: 431002 | O32: Vamsi reddy Peddinti | P32: 9381863414 | Q32: vamsipeddinti28@gmail.com | R32: 5.5years | S32: 3years | T32: Nivass IT Solutions Pvt Ltd | U32: 550000 | V32: 850000 | W32: 30days | X32: No | Y32: No | AA32: Hyderabad | AB32: Hyderabad
A33: 32 | B33: Dell FG | C33: 44558 | D33: ​98936697 | E33: Vinay Nambiar | F33: 181547 | G33: Vendor Partner | H33: SRS | I33: Java | J33: Java/J2EE,Full Stack Developer,Spring Boot,Angular,Cloud Technologies | K33: Joined | L33: Joined because of high CTC | M33: Regular | N33: 351658 | O33: Yashwanth Vyamasani | P33: 9949073900 | Q33: yashwanth.vyam@gmail.com | R33: 13 yr | S33: 13 yr | T33: IBM | U33: 1230000 | V33: 3000000 | W33: ELWD : 21/01/22 | X33: No | Y33: No | AA33: HYDERABAD | AB33: HYDERABAD
A34: 33 | B34: Dell FG | C34: 44558 | D34: ​98936697 | E34: Vinay Nambiar | F34: 181547 | G34: Vendor Partner | H34: SRS | I34: Java | J34: Java/J2EE,Full Stack Developer,Spring Boot,Angular,Cloud Technologies | K34: Feedback pending from client | L34: Processed yet to get feedback from client | M34: Regular | N34: 432232 | O34: Chiranjeevi Madasu | P34: 9848869290 | Q34: chiranjeevi.madasu@gmail.com | R34: 15 yr | S34: 15 yr | T34: Infosys | U34: 1600000 | V34: 3000000 | W34: Immediate joiner | X34: No | Y34: No | AA34: HYDERABAD | AB34: HYDERABAD
A35: 34 | B35: Dell FG | C35: 44558 | D35: 95801483 | E35: Vinay Nambiar | F35: 181547 | G35: Vendor Partner | H35: SRS | I35: Java | J35: JAVA/J2EE SPRING, ANGULAR | K35: Joined | L35: Not responding | M35: Regular | N35: H7777151 | O35: M Anil Kumar | P35: 9538824541 | Q35: anelkumar.m159@gmail.com | R35: 6 yr | S35: 6 yr | T35: Tech Mahindra | U35: 750000 | V35: 1500000 | W35: ELWD : 29/01/22 | X35: No | Y35: No | AA35: Bangalore/ | AB35: Bangalore
A36: 35 | B36: Dell FG | C36: 44558 | D36: 95801483 | E36: Vinay Nambiar | F36: 181547 | G36: Vendor Partner | H36: SRS | I36: Java | J36: JAVA/J2EE SPRING ANGULAR | K36: Joined | L36: Not responding | M36: Regular | N36: 328950 | O36: Ravikanth Sharma | P36: 8639575493 | Q36: vrksharma1981@gmail.com | R36: 8yr | S36: 8yr | T36: DXC Technology | U36: 1000000 | V36: 1900000 | W36: ELWD : 21/01/22 | X36: No | Y36: No | AA36: Bangalore/ | AB36: Bangalore
A37: 36 | B37: Dell FG | C37: 44558 | D37: 95801483 | E37: Vinay Nambiar | F37: 181547 | G37: Vendor Partner | H37: SRS | I37: Java | J37: JAVA/J2EE SPRING ANGULAR | K37: Joined | L37: Not responding | M37: Regular | N37: L757477 | O37: Tarun Barik | P37: 7828724103 | Q37: tarunbarik.csit@gmail.com | R37: 6 yr | S37: 6 yr | T37: Slk Software Services | U37: 790000 | V37: 1900000 | W37: ELWD : 25/01/22 | X37: No | Y37: No | AA37: Bangalore/ | AB37: Bangalore
A38: 37 | B38: Dell FG | C38: 44558 | D38: 95801483 | E38: Vinay Nambiar | F38: 181547 | G38: Vendor Partner | H38: SRS | I38: Java | J38: Java/J2EE, Angularjs,Spring Boot | K38: Joined | L38: Not responding | M38: Regular | N38: 432194 | O38: Selva Kumar G | P38: 9500552392 | Q38: selva.kak@gmail.com | R38: 5.5 Years | S38: 5.5 Years | T38: Smartpoint Technologies | U38: 890000 | V38: 1500000 | W38: LWD 04-02-2022 | X38: Yes | Y38: No | AA38: Chennai | AB38: Banglore
A39: 38 | B39: Dell FG | C39: 44558 | D39: 98927307 | E39: Vinay Nambiar | F39: 181547 | G39: Vendor Partner | H39: SRS | I39: Java | J39: 3-6y Java/J2EE,Springboot,Cloud Native Concepts,RESTful,web services,Microservice Architecture,Spring Framework | K39: Joined | L39: No show | M39: Regular | N39: 433908 | O39: Manoj kumar | P39: 8143524153 | Q39: manojkumar.yerukondu@gmail.com | R39: 3.2 years | S39: 2 yrs | T39: Infosys | U39: 660000 | V39: 1000000 | W39: LWD: 31/12/2021 | X39: No | Y39: No | AA39: Hyderabad | AB39: Bangalore
A40: 39 | B40: Dell FG | C40: 44558 | D40: 98927307 | E40: Vinay Nambiar | F40: 181547 | G40: Vendor Partner | H40: SRS | I40: Java | J40: 3-6y Java/J2EE,Springboot,Cloud Native Concepts,RESTful,web services,Microservice Architecture,Spring Framework | K40: Dropped | L40: Candidate has other offer not processed | M40: Regular | N40: 433941 | O40: G. Ganesh | P40: 7893030070 | Q40: gampalaganesh05@gmail.com | R40: 2.4 years | S40: 2 yrs | T40: Sun Icon systems Pvt. Ltd | U40: 480000 | V40: 1000000 | W40: 30 days | X40: No | Y40: No | AA40: Hyderabad | AB40: Hyderabad
...

Sheet Questions
H6: 1): we have to show dashboard for
H7: 2): The candidates joined in different years
H8: 3): show top 5 skills hired in 2024
H9: 4): Top 3 locations from where we hired
H10: 5): Top 2 locations candidates preffered
H11: 6): Reqruiter performance: Joiner per reqruiter
H12: 7): Total offered, Total joined, offered to joining percentage
H13: 8): Total salary offered in one year
H14: 9): experience range 0-5, 5-10,10-15,15-20
H15: 10): data cleanup

Sheet  Q55
A3: Row Labels | B3: Count of Preferred Location
A4: Bangalore | B4: 569
A5: Hyderabad | B5: 147
A6: Grand Total | B6: 716

Sheet Q22
A3: Row Labels | B3: Count of Candidate Status
A4: 2021 | B4: 36
A5: 2022 | B5: 689
A6: Grand Total | B6: 725

Sheet Dashboard 2

Sheet Q33
A3: Row Labels | B3: Count of Mandatory Skill
A4: SDET | B4: 79
A5: Java | B5: 69
A6: Java Developer | B6: 42
A7: DOTNET | B7: 37
A8: UI Developer | B8: 23
A9: DW/EBI | B9: 23
A10: Grand Total | B10: 273

Sheet Q44
A3: Row Labels | B3: Count of Current Location
A4: Bangalore | B4: 331
A5: Hyderabad | B5: 185
A6: Pune | B6: 35
A7: Chennai | B7: 35
A8: Grand Total | B8: 586

Sheet Q66
A3: Row Labels | B3: Count of Candidate Status
A4: Divakara Rangaswamy | B4: 11
A5: Rahul Kapoor | B5: 72
A6: Dinesh Shiranpel | B6: 124
A7: Vinay Nambiar | B7: 176
A8: Febha John | B8: 342
A9: Grand Total | B9: 725

Sheet Q88
A3: Row Labels | B3: Sum of CTC
A4: 2021 | B4: 36575000
A5: 2022 | B5: 724796600
A6: Grand Total | B6: 761371600

Sheet Q99
A3: Row Labels | B3: Count of Year of Exp
A4: 1-5 | B4: 327
A5: 6-10 | B5: 343
A6: 11-15 | B6: 48
A7: 16-20 | B7: 4
A8: 26-30 | B8: 1
A9: 31-35 | B9: 2
A10: Grand Total | B10: 725

Sheet Candidate Data &Q7
A1: Sl.No | B1: Account | C1: Profile Submission Date | D1: SO Number | E1: Reqruiter Name | F1: Employee ID | G1: Source | H1: Sub Source | I1: Mandatory Skill | J1: Skill Combinations | K1: Candidate Status | L1: Detailed Status | M1: Hire Type | N1: Candidate ID | O1: Candidate Name | P1: Contact Number | Q1: Email id | R1: Total Yrs of Exp | S1: Current Company | T1: CTC | U1: Notice Period | V1: Ex-Employee(Y/N) | W1: Current Location | X1: Preferred Location | Y1: Month of Profile Submission | Z1: Year of Profile Submission | AA1: YO1 | AB1: YO2 | AC1: YO3 | AD1: YO4 | AE1: YO5 | AF1: YO6 | AG1: Year of Exp
A2: 1 | B2: Dell FG | C2: 44546 | D2: 38024355 | E2: Rahul Kapoor | F2: U82721 | G2: Vendor Partner | H2: Mindsoft | I2: Java Selenium | J2: JAVA SELENIUM | K2: Dropped | L2: Back up candidates | M2: Regular | N2: 484611 | O2: Jacob | P2: 9553801682 | Q2: jacobkoheer@gmail.com | R2: 3yrs | S2: Sun icon | T2: 600000 | U2: LWD-Dec 22nd-Immediate | V2: N | W2: Hyderabad | X2: Bangalore | Y2: =MONTH($C2) -> 12 | Z2: =YEAR($C2) -> 2021 | AA2: =LEFT(R2,2) -> 3y | AB2: =SUBSTITUTE(AA2,"y","") -> 3 | AC2: =SUBSTITUTE(AB2,".","") -> 3 | AD2: =SUBSTITUTE(AC2,"+","") -> 3 | AE2: =SUBSTITUTE(AD2,"Y","") -> 3 | AF2: =SUBSTITUTE(AE2,"e","") -> 3 | AG2: =SUBSTITUTE(AF2,",","")*1 -> 3
A3: 2 | B3: Dell FG | C3: 44550 | D3: 38024355 | E3: Rahul Kapoor | F3: U82721 | G3: Vendor Partner | H3: Mindsoft | I3: SDET | J3: JAVA SELENIUM | K3: Tech1 Reject | L3: Screening IP | M3: Regular | N3: 351671 | O3: T M NANDINI | P3: 9739829708 | Q3: nandini.m.t78@gmail.com | R3: 3.4yrs | S3: Mindtree | T3: 550000 | U3: LWD-JAN 25TH | V3: N | W3: Bangalore | X3: Bangalore | Y3: =MONTH($C3) -> 12 | Z3: =YEAR($C3) -> 2021 | AA3: =LEFT(R3,2) -> 3. | AB3: =SUBSTITUTE(AA3,"y","") -> 3. | AC3: =SUBSTITUTE(AB3,".","") -> 3 | AD3: =SUBSTITUTE(AC3,"+","") -> 3 | AE3: =SUBSTITUTE(AD3,"Y","") -> 3 | AF3: =SUBSTITUTE(AE3,"e","") -> 3 | AG3: =SUBSTITUTE(AF3,",","")*1 -> 3
A4: 3 | B4: Dell FG | C4: 44550 | D4: 94967553 | E4: Rahul Kapoor | F4: U82721 | G4: UST Global | H4: Mindsoft | I4: QA , Manual tester role | J4: SDET | K4: Dropped | L4: Rejected | M4: Regular | N4: 354205 | O4: Vaishali Dixit | P4: 9691520066 | Q4: dixit.vaishali08@gmail.com | R4: 3.5yrs | S4: Capgemini | T4: 450000 | U4: 30 days(LWD: 26th Jan) | V4: N | W4: Bangalore | X4: Bangalore | Y4: =MONTH($C4) -> 12 | Z4: =YEAR($C4) -> 2021 | AA4: =LEFT(R4,2) -> 3. | AB4: =SUBSTITUTE(AA4,"y","") -> 3. | AC4: =SUBSTITUTE(AB4,".","") -> 3 | AD4: =SUBSTITUTE(AC4,"+","") -> 3 | AE4: =SUBSTITUTE(AD4,"Y","") -> 3 | AF4: =SUBSTITUTE(AE4,"e","") -> 3 | AG4: =SUBSTITUTE(AF4,",","")*1 -> 3
A5: 4 | B5: Dell FG | C5: 44550 | D5: 31972088 | E5: Vinay Nambiar | F5: 181547 | G5: Vendor Partner | H5: SRS | I5: Java | J5: Java/J2EE,Spring Boot,Spring Core,Spring MVC, Spring Web Services, Spring boot, Spring Data, Spring Cloud,HTML/CSS/JS | K5: Joined | L5: Interview No show | M5: Regular | N5: 419101 | O5: Hema Latha | P5: 9948358570 | Q5: hemalatha.friends@gmail.com | R5: 14 yr | S5: Infosys | T5: 1450000 | U5: LWD : 4/1/2021 | V5: N | W5: Hyderabad | X5: Hyderabad | Y5: =MONTH($C5) -> 12 | Z5: =YEAR($C5) -> 2021 | AA5: =LEFT(R5,2) -> 14 | AB5: =SUBSTITUTE(AA5,"y","") -> 14 | AC5: =SUBSTITUTE(AB5,".","") -> 14 | AD5: =SUBSTITUTE(AC5,"+","") -> 14 | AE5: =SUBSTITUTE(AD5,"Y","") -> 14 | AF5: =SUBSTITUTE(AE5,"e","") -> 14 | AG5: =SUBSTITUTE(AF5,",","")*1 -> 14 | AI5: Total Joined | AJ5: =COUNTIF(K2:K3040,"Joined") -> 725
A6: 5 | B6: Dell FG | C6: 44551 | D6: 94967553 | E6: Rahul Kapoor | F6: U82721 | G6: UST Global | H6: Mindsoft | I6: QA , Manual tester role:- | J6: SDET | K6: Joined | L6: Rejected | M6: Regular | N6: 379458 | O6: Alekya | P6: 9441095144 | Q6: alekya.d1988@gmail.com | R6: 4.8yrs | S6: Nuance Transcription | T6: 500000 | U6: Immediate | V6: N | W6: Bangalore | X6: Bangalore | Y6: =MONTH($C6) -> 12 | Z6: =YEAR($C6) -> 2021 | AA6: =LEFT(R6,2) -> 4. | AB6: =SUBSTITUTE(AA6,"y","") -> 4. | AC6: =SUBSTITUTE(AB6,".","") -> 4 | AD6: =SUBSTITUTE(AC6,"+","") -> 4 | AE6: =SUBSTITUTE(AD6,"Y","") -> 4 | AF6: =SUBSTITUTE(AE6,"e","") -> 4 | AG6: =SUBSTITUTE(AF6,",","")*1 -> 4 | AI6: Total Declined | AJ6: =COUNTIF(K2:K3040,"Declined") -> 73
A7: 6 | B7: Dell FG | C7: 44551 | D7: 82866188 | E7: Rahul Kapoor | F7: U82721 | G7: UST Global | H7: Mindsoft | I7: UI/UX role | J7: UI | K7: Dropped | L7: Drop out | M7: Regular | N7: 355575 | O7: Rajesh Sah | P7: 9739607439 | Q7: codeuix@gmail.com | R7: 6 years | S7: Nubewell Networks Pvt Ltd | T7: 1500000 | U7: 11-Jan LWD | V7: N | W7: Bangalore | X7: Bangalore | Y7: =MONTH($C7) -> 12 | Z7: =YEAR($C7) -> 2021 | AA7: =LEFT(R7,2) -> 6 | AB7: =SUBSTITUTE(AA7,"y","") -> 6 | AC7: =SUBSTITUTE(AB7,".","") -> 6 | AD7: =SUBSTITUTE(AC7,"+","") -> 6 | AE7: =SUBSTITUTE(AD7,"Y","") -> 6 | AF7: =SUBSTITUTE(AE7,"e","") -> 6 | AG7: =SUBSTITUTE(AF7,",","")*1 -> 6 | AI7: Total Offered | AJ7: =$AJ$5+$AJ$6 -> 798
A8: 7 | B8: Dell FG | C8: 44551 | D8: 82866188 | E8: Rahul Kapoor | F8: U82721 | G8: UST Global | H8: Mindsoft | I8: UI/UX role | J8: UI | K8: Dropped | L8: Drop out | M8: Regular | N8: H8271088 | O8: Ankita Awasthi | P8: 9717348292 | Q8: ankitaawasthi05@gmail.com | R8: 7.6years | S8: Genpact | T8: 1000000 | U8: 29-Dec LWD | V8: N | W8: Bangalore | X8: Bangalore | Y8: =MONTH($C8) -> 12 | Z8: =YEAR($C8) -> 2021 | AA8: =LEFT(R8,2) -> 7. | AB8: =SUBSTITUTE(AA8,"y","") -> 7. | AC8: =SUBSTITUTE(AB8,".","") -> 7 | AD8: =SUBSTITUTE(AC8,"+","") -> 7 | AE8: =SUBSTITUTE(AD8,"Y","") -> 7 | AF8: =SUBSTITUTE(AE8,"e","") -> 7 | AG8: =SUBSTITUTE(AF8,",","")*1 -> 7 | AI8: Offered to Joined Percentage | AJ8: =($AJ$5/$AJ$7)*100 -> 90.85213
A9: 8 | B9: Dell FG | C9: 44551 | D9: 51907700 | E9: Vinay Nambiar | F9: 181547 | G9: Vendor Partner | H9: SRS | I9: Java | J9: Java/J2EE,Spring Boot,Spring Core,Spring MVC, Spring Web Services, Spring boot, Spring Data, Spring Cloud,HTML/CSS/JS | K9: Joined | L9: Not responding | M9: Regular | N9: H14387 | O9: Sreedhar Vinjamuri | P9: 7337067133 | Q9: sreedhar.vin12@gmail.com | R9: 13 yr | S9: Virinchi Technologies | T9: 1500000 | U9: IMMEDATE JOINNER | V9: N | W9: Hyderabad | X9: Hyderabad | Y9: =MONTH($C9) -> 12 | Z9: =YEAR($C9) -> 2021 | AA9: =LEFT(R9,2) -> 13 | AB9: =SUBSTITUTE(AA9,"y","") -> 13 | AC9: =SUBSTITUTE(AB9,".","") -> 13 | AD9: =SUBSTITUTE(AC9,"+","") -> 13 | AE9: =SUBSTITUTE(AD9,"Y","") -> 13 | AF9: =SUBSTITUTE(AE9,"e","") -> 13 | AG9: =SUBSTITUTE(AF9,",","")*1 -> 13
A10: 9 | B10: Dell FG | C10: 44551 | D10: 57335575 | E10: Vinay Nambiar | F10: 181547 | G10: Vendor Partner | H10: SRS | I10: Java | J10: Java/J2EE,Spring Boot,Spring Core,Spring MVC, Spring Web Services, Spring boot, Spring Data, Spring Cloud,HTML/CSS/JS | K10: Joined | L10: Interview No show | M10: Regular | N10: 419812 | O10: Pokuri Ramanjaneyulu | P10: 8106332319 | Q10: ram1980.p@gmail.com | R10: 14 yr | S10: HCL Technologies, | T10: 1450000 | U10: LWD: 28/1/2021 | V10: N | W10: Hyderabad | X10: Hyderabad | Y10: =MONTH($C10) -> 12 | Z10: =YEAR($C10) -> 2021 | AA10: =LEFT(R10,2) -> 14 | AB10: =SUBSTITUTE(AA10,"y","") -> 14 | AC10: =SUBSTITUTE(AB10,".","") -> 14 | AD10: =SUBSTITUTE(AC10,"+","") -> 14 | AE10: =SUBSTITUTE(AD10,"Y","") -> 14 | AF10: =SUBSTITUTE(AE10,"e","") -> 14 | AG10: =SUBSTITUTE(AF10,",","")*1 -> 14
A11: 10 | B11: Dell FG | C11: 44551 | D11: 94990037 | E11: Vinay Nambiar | F11: 181547 | G11: Vendor Partner | H11: SRS | I11: Java | J11: Java/J2EE,Spring Boot,Spring Core,Spring MVC, Spring Web Services, Spring boot, Spring Data, Spring Cloud,HTML/CSS/JS | K11: Joined | L11: Interview No show | M11: Regular | N11: 418251 | O11: Sailaja Malyala | P11: 9848623920 | Q11: sailajamalyal@gmail.com | R11: 14 yr | S11: IBM | T11: 1200000 | U11: ELWD : 26/01/22 | V11: N | W11: Hyderabad | X11: Hyderabad | Y11: =MONTH($C11) -> 12 | Z11: =YEAR($C11) -> 2021 | AA11: =LEFT(R11,2) -> 14 | AB11: =SUBSTITUTE(AA11,"y","") -> 14 | AC11: =SUBSTITUTE(AB11,".","") -> 14 | AD11: =SUBSTITUTE(AC11,"+","") -> 14 | AE11: =SUBSTITUTE(AD11,"Y","") -> 14 | AF11: =SUBSTITUTE(AE11,"e","") -> 14 | AG11: =SUBSTITUTE(AF11,",","")*1 -> 14
A12: 11 | B12: Dell FG | C12: 44552 | D12: 44173531 | E12: Vinay Nambiar | F12: 181547 | G12: Vendor Partner | H12: SRS | I12: Java | J12: Java/J2EE, Angularjs | K12: Dropped | L12: Not interested | M12: Regular | N12: 421816 | O12: G.Ramana Reddy | P12: 9390911344 | Q12: grreddy1729@gmail.com | R12: 5 Years | S12: L&T Infotech | T12: 900000 | U12: LWD 30-01-2022 | V12: N | W12: Hyderabad | X12: Hyderabad | Y12: =MONTH($C12) -> 12 | Z12: =YEAR($C12) -> 2021 | AA12: =LEFT(R12,2) -> 5 | AB12: =SUBSTITUTE(AA12,"y","") -> 5 | AC12: =SUBSTITUTE(AB12,".","") -> 5 | AD12: =SUBSTITUTE(AC12,"+","") -> 5 | AE12: =SUBSTITUTE(AD12,"Y","") -> 5 | AF12: =SUBSTITUTE(AE12,"e","") -> 5 | AG12: =SUBSTITUTE(AF12,",","")*1 -> 5
A13: 12 | B13: Dell FG | C13: 44552 | D13: 44173531 | E13: Vinay Nambiar | F13: 181547 | G13: Vendor Partner | H13: SRS | I13: Java | J13: Java/J2EE, Angularjs | K13: Screen Reject | L13: Not responding | M13: Regular | N13: 421822 | O13: Prem Kumar Jannu | P13: 7893092220 | Q13: prem.jannu182829@gamil.com | R13: 9 Years | S13: Infosys LTD | T13: 1200000 | U13: LWD 31-01-2022 | V13: N | W13: Hyderabad | X13: Hyderabad | Y13: =MONTH($C13) -> 12 | Z13: =YEAR($C13) -> 2021 | AA13: =LEFT(R13,2) -> 9 | AB13: =SUBSTITUTE(AA13,"y","") -> 9 | AC13: =SUBSTITUTE(AB13,".","") -> 9 | AD13: =SUBSTITUTE(AC13,"+","") -> 9 | AE13: =SUBSTITUTE(AD13,"Y","") -> 9 | AF13: =SUBSTITUTE(AE13,"e","") -> 9 | AG13: =SUBSTITUTE(AF13,",","")*1 -> 9
A14: 13 | B14: Dell FG | C14: 44552 | D14: 67489866 | E14: Vinay Nambiar | F14: 181547 | G14: Vendor Partner | H14: SRS | I14: DevOps | J14: 5-8y Devops with GIT,CICD (Gitlab),Powershell/Bash | K14: Dropped | L14: Requirement closed | M14: Regular | N14: 421830 | O14: Srinivas. Y | P14: 8247858588 | Q14: srinivasyara1257@gmail.com | R14: 5.3years | S14: Sciens Software Technologies | T14: 650000 | U14: 25days | V14: N | W14: Hyderabad | X14: Hyderabad | Y14: =MONTH($C14) -> 12 | Z14: =YEAR($C14) -> 2021 | AA14: =LEFT(R14,2) -> 5. | AB14: =SUBSTITUTE(AA14,"y","") -> 5. | AC14: =SUBSTITUTE(AB14,".","") -> 5 | AD14: =SUBSTITUTE(AC14,"+","") -> 5 | AE14: =SUBSTITUTE(AD14,"Y","") -> 5 | AF14: =SUBSTITUTE(AE14,"e","") -> 5 | AG14: =SUBSTITUTE(AF14,",","")*1 -> 5
A15: 14 | B15: Dell FG | C15: 44553 | D15: 94967553 | E15: Rahul Kapoor | F15: U82721 | G15: UST Global | H15: Mindsoft | I15: QA , Manual tester role | J15: SDET | K15: Dropped | L15: Pending | M15: Regular | N15: 389073 | O15: Vishnu kumar | P15: 9390839924 | Q15: m.vishnu225@gmail.com | R15: 3 yrs | S15: Brillquest technologies Pvt Ltd | T15: 300000 | U15: LWD-3rd Jan 22 | V15: N | W15: Bangalore | X15: Bangalore | Y15: =MONTH($C15) -> 12 | Z15: =YEAR($C15) -> 2021 | AA15: =LEFT(R15,2) -> 3 | AB15: =SUBSTITUTE(AA15,"y","") -> 3 | AC15: =SUBSTITUTE(AB15,".","") -> 3 | AD15: =SUBSTITUTE(AC15,"+","") -> 3 | AE15: =SUBSTITUTE(AD15,"Y","") -> 3 | AF15: =SUBSTITUTE(AE15,"e","") -> 3 | AG15: =SUBSTITUTE(AF15,",","")*1 -> 3
A16: 15 | B16: Dell FG | C16: 44553 | D16: 67489866 | E16: Vinay Nambiar | F16: 181547 | G16: Vendor Partner | H16: SRS | I16: DevOps | J16: 5-8y Devops with GIT,CICD (Gitlab),Powershell/Bash | K16: Dropped | L16: Requirement closed | M16: Regular | N16: 421842 | O16: Tejaswi Jonnalagadda | P16: 6302517658 | Q16: tejaswi.jonnalagadda91@gmail.com | R16: 7.2years | S16: Cognizant | T16: 510000 | U16: 30days | V16: N | W16: Hyderabad | X16: Hyderabad | Y16: =MONTH($C16) -> 12 | Z16: =YEAR($C16) -> 2021 | AA16: =LEFT(R16,2) -> 7. | AB16: =SUBSTITUTE(AA16,"y","") -> 7. | AC16: =SUBSTITUTE(AB16,".","") -> 7 | AD16: =SUBSTITUTE(AC16,"+","") -> 7 | AE16: =SUBSTITUTE(AD16,"Y","") -> 7 | AF16: =SUBSTITUTE(AE16,"e","") -> 7 | AG16: =SUBSTITUTE(AF16,",","")*1 -> 7
A17: 16 | B17: Dell FG | C17: 44553 | D17: 98936697 | E17: Vinay Nambiar | F17: 181547 | G17: Vendor Partner | H17: SRS | I17: Java | J17: Java/J2EE,Full Stack Developer,Spring Boot,Angular,Cloud Technologies | K17: Screen Reject | L17: Not responding | M17: Regular | N17: 422936 | O17: Raja Mohan Munjeti | P17: 9492543488 | Q17: mohan123.java@gmail.com | R17: 14 yr | S17: Birlasoft | T17: 1300000 | U17: LWD 20/1/2022 | V17: N | W17: Hyderabad | X17: Hyderabad | Y17: =MONTH($C17) -> 12 | Z17: =YEAR($C17) -> 2021 | AA17: =LEFT(R17,2) -> 14 | AB17: =SUBSTITUTE(AA17,"y","") -> 14 | AC17: =SUBSTITUTE(AB17,".","") -> 14 | AD17: =SUBSTITUTE(AC17,"+","") -> 14 | AE17: =SUBSTITUTE(AD17,"Y","") -> 14 | AF17: =SUBSTITUTE(AE17,"e","") -> 14 | AG17: =SUBSTITUTE(AF17,",","")*1 -> 14
